<?xml version="1.0"?>
<robot name="storper" xmlns:xacro="http://www.ros.org/wiki/xacro">

  <!-- Links -->
  <link name="base_link">
    <inertial>
      <mass value="1.0"/>
      <origin xyz="0 0 0" rpy="0 0 0"/>
      <inertia ixx="0.01" ixy="0.0" ixz="0.0" iyy="0.01" iyz="0.0" izz="0.01"/>
    </inertial>
    <visual>
      <geometry>
        <box size="0.2 0.15 0.05"/>
      </geometry>
      <material name="blue">
        <color rgba="0 0 1 1"/>
      </material>
    </visual>
    <collision>
      <geometry>
        <box size="0.2 0.15 0.05"/>
      </geometry>
    </collision>
  </link>

  <link name="left_wheel_link">
    <visual>
      <geometry>
        <cylinder length="0.02" radius="0.03"/>
      </geometry>
      <material name="black">
        <color rgba="0 0 0 1"/>
      </material>
    </visual>
    <collision>
      <geometry>
        <cylinder length="0.02" radius="0.03"/>
      </geometry>
    </collision>
  </link>

  <link name="right_wheel_link">
    <visual>
      <geometry>
        <cylinder length="0.02" radius="0.03"/>
      </geometry>
      <material name="black">
        <color rgba="0 0 0 1"/>
      </material>
    </visual>
    <collision>
      <geometry>
        <cylinder length="0.02" radius="0.03"/>
      </geometry>
    </collision>
  </link>

  <!-- Joints -->
  <joint name="left_wheel_joint" type="continuous">
    <parent link="base_link"/>
    <child link="left_wheel_link"/>
    <origin xyz="0.0 0.075 0.0" rpy="0 0 0"/>
    <axis xyz="0 1 0"/>
  </joint>

  <joint name="right_wheel_joint" type="continuous">
    <parent link="base_link"/>
    <child link="right_wheel_link"/>
    <origin xyz="0.0 -0.075 0.0" rpy="0 0 0"/>
    <axis xyz="0 1 0"/>
  </joint>

  <!-- World link -->
  <link name="world"/>
  <joint name="world_joint" type="fixed">
    <parent link="world"/>
    <child link="base_link"/>
  </joint>

  <!-- Gazebo diff_drive plugin attached correctly -->
  <gazebo reference="base_link">
    <plugin name="diff_drive_controller" filename="libgazebo_ros_diff_drive.so">
      <!-- ros>
        <remapping>cmd_vel:=/rt/cmd_vel</remapping>
      </ros -->
      <update_rate>50</update_rate>
      <left_wheel>left_wheel_joint</left_wheel>
      <right_wheel>right_wheel_joint</right_wheel>
      <wheel_separation>0.15</wheel_separation>
      <wheel_radius>0.03</wheel_radius>
      <command_topic>/rt/cmd_vel</command_topic>
      <odometry_topic>/odom</odometry_topic>
      <odometry_frame>odom</odometry_frame>
      <robot_base_frame>base_link</robot_base_frame>
      <publish_odom>true</publish_odom>
      <publish_tf>true</publish_tf>
    </plugin>
  </gazebo>

</robot>

